Workbook

Sheet 卡牌数值
A1: 戈克世界：流脉牌局 · 稳定版卡牌数值调整表
A2: 稳定构建 20261020e24.5 · 244 个可收藏条目 + 8 个衍生物 · 直接修改黄色列，P 列自动标记改动
A3: 编辑范围：F 费用 / G 攻击 / H 生命；M-O 是原始值，P 列自动判断是否已改。
A5: ID | B5: 卡牌名 | C5: 阵营 | D5: 类型 | E5: 稀有度 | F5: 费用 | G5: 攻击 | H5: 生命 | I5: 牌组上限 | J5: 关键词 | K5: 卡牌文本 | L5: 效果类型 | M5: 原费用 | N5: 原攻击 | O5: 原生命 | P5: 改动 | Q5: 状态 | R5: 备注
A6: medic_apprentice | B6: 医疗学徒 | C6: 普卫岛 | D6: 随从 | E6: 普通 | F6: 1 | G6: 1 | H6: 2 | I6: 2 | K6: 引脉 4/8：恢复你的领袖 1/3 点生命。 | L6: veinTiers:2 | M6: 1 | N6: 1 | O6: 2 | P6: =IF(OR(F6<>M6,IF(AND(G6="",N6=""),FALSE,G6<>N6),IF(AND(H6="",O6=""),FALSE,H6<>O6)),"已改","") | Q6: 可组
A7: courier | B7: 协调部信使 | C7: 普卫岛 | D7: 随从 | E7: 普通 | F7: 1 | G7: 1 | H7: 2 | I7: 2 | K7: 被动：该随从在场时，同阵位每有一个其他友方随从，本随从获得 +0/+1。 | L7: zoneBonus:object | M7: 1 | N7: 1 | O7: 2 | P7: =IF(OR(F7<>M7,IF(AND(G7="",N7=""),FALSE,G7<>N7),IF(AND(H7="",O7=""),FALSE,H7<>O7)),"已改","") | Q7: 可组
A8: vein_scout | B8: 引脉斥候 | C8: 普卫岛 | D8: 随从 | E8: 普通 | F8: 1 | G8: 2 | H8: 1 | I8: 2 | J8: 突进 | K8: 突进。引脉 3：获得 +0/+1。 | L8: veinTiers:1 | M8: 1 | N8: 2 | O8: 1 | P8: =IF(OR(F8<>M8,IF(AND(G8="",N8=""),FALSE,G8<>N8),IF(AND(H8="",O8=""),FALSE,H8<>O8)),"已改","") | Q8: 可组
A9: vein_attendant | B9: 引脉侍从 | C9: 普卫岛 | D9: 随从 | E9: 稀有 | F9: 2 | G9: 2 | H9: 2 | I9: 2 | J9: 登场 | K9: 登场：流脉 +1。引脉 3：获得 +1/+1。 | L9: battlecry:veinOnly；veinTiers:1 | M9: 2 | N9: 2 | O9: 2 | P9: =IF(OR(F9<>M9,IF(AND(G9="",N9=""),FALSE,G9<>N9),IF(AND(H9="",O9=""),FALSE,H9<>O9)),"已改","") | Q9: 可组
A10: vein_foreman | B10: 掘脉工头 | C10: 普卫岛 | D10: 随从 | E10: 普通 | F10: 2 | G10: 2 | H10: 1 | I10: 2 | J10: 登场 | K10: 采掘 1；登场：抽 1 张牌。 | L10: battlecry:draw | M10: 2 | N10: 2 | O10: 1 | P10: =IF(OR(F10<>M10,IF(AND(G10="",N10=""),FALSE,G10<>N10),IF(AND(H10="",O10=""),FALSE,H10<>O10)),"已改","") | Q10: 可组
A11: timon | B11: 提蒙 | C11: 普卫岛 | D11: 随从 | E11: 传说 | F11: 3 | G11: 3 | H11: 2 | I11: 1 | J11: 被动 | K11: 被动：提蒙存活时，你每个回合打出的第一张牌行动力消耗 -1。 | L11: passive:firstCardDiscount | M11: 3 | N11: 3 | O11: 2 | P11: =IF(OR(F11<>M11,IF(AND(G11="",N11=""),FALSE,G11<>N11),IF(AND(H11="",O11=""),FALSE,H11<>O11)),"已改","") | Q11: 可组
A12: orlicas | B12: 欧莉卡斯 | C12: 普卫岛 | D12: 随从 | E12: 传说 | F12: 3 | G12: 2 | H12: 2 | I12: 1 | J12: 登场 | K12: 登场：抽 1 张牌；引脉 4：再抽 1 张牌。 | L12: battlecry:drawVein | M12: 3 | N12: 2 | O12: 2 | P12: =IF(OR(F12<>M12,IF(AND(G12="",N12=""),FALSE,G12<>N12),IF(AND(H12="",O12=""),FALSE,H12<>O12)),"已改","") | Q12: 可组
A13: guard | B13: 保卫部步兵 | C13: 普卫岛 | D13: 随从 | E13: 普通 | F13: 3 | G13: 1 | H13: 4 | I13: 2 | J13: 拦截 | K13: 拦截。被动：该随从在场时，同阵位每有一个其他友方随从，本随从获得 +1/+0。 | L13: zoneBonus:object | M13: 3 | N13: 1 | O13: 4 | P13: =IF(OR(F13<>M13,IF(AND(G13="",N13=""),FALSE,G13<>N13),IF(AND(H13="",O13=""),FALSE,H13<>O13)),"已改","") | Q13: 可组
A14: zone_keeper | B14: 同阵守望者 | C14: 普卫岛 | D14: 随从 | E14: 稀有 | F14: 3 | G14: 3 | H14: 2 | I14: 2 | K14: 被动：该随从在场时，同阵位每有一个其他友方随从，本随从获得 +1/+2。 | L14: zoneBonus:object | M14: 3 | N14: 3 | O14: 2 | P14: =IF(OR(F14<>M14,IF(AND(G14="",N14=""),FALSE,G14<>N14),IF(AND(H14="",O14=""),FALSE,H14<>O14)),"已改","") | Q14: 可组
A15: formation_weaver | B15: 阵线织者 | C15: 普卫岛 | D15: 随从 | E15: 史诗 | F15: 3 | G15: 2 | H15: 3 | I15: 2 | J15: 登场 | K15: 登场：若该卡被召唤到已经使用阵型卡的阵位，获得 +0/+1 并抽 1 张牌。 | L15: battlecry:formationPayoff | M15: 3 | N15: 2 | O15: 3 | P15: =IF(OR(F15<>M15,IF(AND(G15="",N15=""),FALSE,G15<>N15),IF(AND(H15="",O15=""),FALSE,H15<>O15)),"已改","") | Q15: 可组
A16: spring_medic | B16: 涌泉医师 | C16: 普卫岛 | D16: 随从 | E16: 普通 | F16: 3 | G16: 2 | H16: 3 | I16: 2 | J16: 登场 | K16: 登场：恢复所有友方随从 2 点生命。 | L16: battlecry:healAllAllies | M16: 3 | N16: 2 | O16: 3 | P16: =IF(OR(F16<>M16,IF(AND(G16="",N16=""),FALSE,G16<>N16),IF(AND(H16="",O16=""),FALSE,H16<>O16)),"已改","") | Q16: 可组
A17: shextena | B17: 希斯蒂娜 | C17: 普卫岛 | D17: 随从 | E17: 传说 | F17: 4 | G17: 3 | H17: 3 | I17: 1 | J17: 登场 | K17: 登场：恢复你的领袖 3 点生命；每实际恢复 1 点，希斯蒂娜获得 +1/+1。引脉 10：恢复你的领袖 3 点生命。 | L17: battlecry:healHeroSelfBuff；veinTiers:1 | M17: 4 | N17: 3 | O17: 3 | P17: =IF(OR(F17<>M17,IF(AND(G17="",N17=""),FALSE,G17<>N17),IF(AND(H17="",O17=""),FALSE,H17<>O17)),"已改","") | Q17: 可组
A18: verious | B18: 维里欧斯 | C18: 普卫岛 | D18: 随从 | E18: 传说 | F18: 4 | G18: 4 | H18: 2 | I18: 1 | J18: 登场 | K18: 登场：沉默一个敌方随从；引脉 5：获得 +0/+2。 | L18: battlecry:silenceVeinBuff | M18: 4 | N18: 4 | O18: 2 | P18: =IF(OR(F18<>M18,IF(AND(G18="",N18=""),FALSE,G18<>N18),IF(AND(H18="",O18=""),FALSE,H18<>O18)),"已改","") | Q18: 可组
A19: aidric | B19: 艾德里克 | C19: 普卫岛 | D19: 随从 | E19: 传说 | F19: 4 | G19: 2 | H19: 4 | I19: 1 | J19: 拦截 | K19: 拦截。引脉 4/8：获得 +1/+1 / +2/+2。登场：若该随从对位有敌方随从，获得 3 点护甲。 | L19: mirrorBonus:object；veinTiers:2 | M19: 4 | N19: 2 | O19: 4 | P19: =IF(OR(F19<>M19,IF(AND(G19="",N19=""),FALSE,G19<>N19),IF(AND(H19="",O19=""),FALSE,H19<>O19)),"已改","") | Q19: 可组
A20: vein_engineer | B20: 引脉工程师 | C20: 普卫岛 | D20: 随从 | E20: 史诗 | F20: 4 | G20: 2 | H20: 3 | I20: 2 | J20: 登场 | K20: 登场：流脉 +2；引脉 6：获得 +1/+1。 | L20: battlecry:veinBuff | M20: 4 | N20: 2 | O20: 3 | P20: =IF(OR(F20<>M20,IF(AND(G20="",N20=""),FALSE,G20<>N20),IF(AND(H20="",O20=""),FALSE,H20<>O20)),"已改","") | Q20: 可组
A21: vein_oracle | B21: 引脉先知 | C21: 普卫岛 | D21: 随从 | E21: 稀有 | F21: 5 | G21: 4 | H21: 5 | I21: 2 | K21: 引脉 6：抽 1 张牌。 | L21: veinTiers:1 | M21: 5 | N21: 4 | O21: 5 | P21: =IF(OR(F21<>M21,IF(AND(G21="",N21=""),FALSE,G21<>N21),IF(AND(H21="",O21=""),FALSE,H21<>O21)),"已改","") | Q21: 可组
A22: miyuki | B22: 深雪 | C22: 普卫岛 | D22: 随从 | E22: 传说 | F22: 6 | G22: 5 | H22: 7 | I22: 1 | J22: 登场 | K22: 登场：冻结场上除自己阵位以外的全部随从，包括友方。被动：深雪在场时，同阵位友方随从不会被冻结。 | L22: battlecry:freezeAllExceptOwnZone | M22: 6 | N22: 5 | O22: 7 | P22: =IF(OR(F22<>M22,IF(AND(G22="",N22=""),FALSE,G22<>N22),IF(AND(H22="",O22=""),FALSE,H22<>O22)),"已改","") | Q22: 可组
A23: excavation_titan | B23: 掘脉泰坦 | C23: 普卫岛 | D23: 随从 | E23: 稀有 | F23: 7 | G23: 5 | H23: 6 | I23: 2 | J23: 登场 | K23: 登场：流脉 +2。引脉 10：获得 +2/+1。 | L23: battlecry:veinOnly；veinTiers:1 | M23: 7 | N23: 5 | O23: 6 | P23: =IF(OR(F23<>M23,IF(AND(G23="",N23=""),FALSE,G23<>N23),IF(AND(H23="",O23=""),FALSE,H23<>O23)),"已改","") | Q23: 可组
A24: resonance | B24: 流脉共鸣 | C24: 普卫岛 | D24: 战术 | E24: 普通 | F24: 1 | I24: 2 | K24: 采掘 1。 | L24: spell:drawGainVein | M24: 1 | P24: =IF(OR(F24<>M24,IF(AND(G24="",N24=""),FALSE,G24<>N24),IF(AND(H24="",O24=""),FALSE,H24<>O24)),"已改","") | Q24: 可组
A25: coordination | B25: 协同调度 | C25: 普卫岛 | D25: 战术 | E25: 普通 | F25: 2 | I25: 2 | K25: 使目标所在阵位的所有随从获得 +1/+1。 | L25: spell:buffZone | M25: 2 | P25: =IF(OR(F25<>M25,IF(AND(G25="",N25=""),FALSE,G25<>N25),IF(AND(H25="",O25=""),FALSE,H25<>O25)),"已改","") | Q25: 可组
A26: emergency | B26: 应急响应 | C26: 普卫岛 | D26: 战术 | E26: 普通 | F26: 2 | I26: 2 | K26: 恢复一个友方随从 2 点生命；抽 1 张牌。 | L26: spell:healDraw | M26: 2 | P26: =IF(OR(F26<>M26,IF(AND(G26="",N26=""),FALSE,G26<>N26),IF(AND(H26="",O26=""),FALSE,H26<>O26)),"已改","") | Q26: 可组
A27: vein_siphon | B27: 引脉虹吸 | C27: 普卫岛 | D27: 战术 | E27: 稀有 | F27: 2 | I27: 2 | K27: 恢复你的领袖 3 点生命；流脉 +2。 | L27: spell:healVein | M27: 2 | P27: =IF(OR(F27<>M27,IF(AND(G27="",N27=""),FALSE,G27<>N27),IF(AND(H27="",O27=""),FALSE,H27<>O27)),"已改","") | Q27: 可组
A28: vein_echo | B28: 地脉回响 | C28: 普卫岛 | D28: 战术 | E28: 普通 | F28: 2 | I28: 2 | K28: 恢复你的领袖 3 点生命，并使流脉 +2；若流脉达到 7，抽 1 张牌。 | L28: spell:healVeinDrawAt | M28: 2 | P28: =IF(OR(F28<>M28,IF(AND(G28="",N28=""),FALSE,G28<>N28),IF(AND(H28="",O28=""),FALSE,H28<>O28)),"已改","") | Q28: 可组
A29: formation_vein | B29: 地脉阵线 | C29: 普卫岛 | D29: 阵型 | E29: 稀有 | F29: 3 | I29: 2 | K29: 该阵位友方随从固定获得余响：恢复你的领袖 1 点生命。 | M29: 3 | P29: =IF(OR(F29<>M29,IF(AND(G29="",N29=""),FALSE,G29<>N29),IF(AND(H29="",O29=""),FALSE,H29<>O29)),"已改","") | Q29: 可组
A30: formation_bastion | B30: 磐石阵线 | C30: 普卫岛 | D30: 阵型 | E30: 稀有 | F30: 4 | I30: 2 | K30: 该阵位友方随从固定获得拦截。 | M30: 4 | P30: =IF(OR(F30<>M30,IF(AND(G30="",N30=""),FALSE,G30<>N30),IF(AND(H30="",O30=""),FALSE,H30<>O30)),"已改","") | Q30: 可组
A31: vein_heart | B31: 地脉之心 | C31: 普卫岛 | D31: 遗物 | E31: 史诗 | F31: 3 | I31: 1 | K31: 遗物：每触发一次引脉，恢复你的领袖 2 点生命。 | M31: 3 | P31: =IF(OR(F31<>M31,IF(AND(G31="",N31=""),FALSE,G31<>N31),IF(AND(H31="",O31=""),FALSE,H31<>O31)),"已改","") | Q31: 遗物
A32: formation_standard | B32: 阵线旗标 | C32: 普卫岛 | D32: 遗物 | E32: 史诗 | F32: 3 | I32: 1 | K32: 遗物：使用过阵型卡的阵位上，所有随从固定获得 +1/+0。 | M32: 3 | P32: =IF(OR(F32<>M32,IF(AND(G32="",N32=""),FALSE,G32<>N32),IF(AND(H32="",O32=""),FALSE,H32<>O32)),"已改","") | Q32: 遗物
A33: doorman | B33: 老门房 | C33: 学院 | D33: 随从 | E33: 普通 | F33: 1 | G33: 1 | H33: 3 | I33: 2 | J33: 拦截 | K33: 拦截。 | M33: 1 | N33: 1 | O33: 3 | P33: =IF(OR(F33<>M33,IF(AND(G33="",N33=""),FALSE,G33<>N33),IF(AND(H33="",O33=""),FALSE,H33<>O33)),"已改","") | Q33: 可组
A34: spell_novice | B34: 法术学徒 | C34: 学院 | D34: 随从 | E34: 普通 | F34: 1 | G34: 1 | H34: 1 | I34: 2 | J34: 登场 | K34: 登场：本回合你的下一张战术牌的行动力消耗 -1。 | L34: battlecry:discountSpellTurn | M34: 1 | N34: 1 | O34: 1 | P34: =IF(OR(F34<>M34,IF(AND(G34="",N34=""),FALSE,G34<>N34),IF(AND(H34="",O34=""),FALSE,H34<>O34)),"已改","") | Q34: 可组
A35: samuel | B35: 塞缪尔·奎因 | C35: 学院 | D35: 随从 | E35: 传说 | F35: 2 | G35: 2 | H35: 2 | I35: 1 | J35: 登场 | K35: 登场：随机冻结一名敌方随从。 | L35: battlecry:randomFreeze | M35: 2 | N35: 2 | O35: 2 | P35: =IF(OR(F35<>M35,IF(AND(G35="",N35=""),FALSE,G35<>N35),IF(AND(H35="",O35=""),FALSE,H35<>O35)),"已改","") | Q35: 可组
A36: reflux_apprentice | B36: 逆流学徒 | C36: 学院 | D36: 随从 | E36: 稀有 | F36: 2 | G36: 2 | H36: 1 | I36: 2 | J36: 登场 | K36: 逆流 1：若本回合你施放过战术牌，抽 1 张牌。 | L36: battlecry:spellDraw | M36: 2 | N36: 2 | O36: 1 | P36: =IF(OR(F36<>M36,IF(AND(G36="",N36=""),FALSE,G36<>N36),IF(AND(H36="",O36=""),FALSE,H36<>O36)),"已改","") | Q36: 可组
A37: justus | B37: 尤斯图斯·维尔纳 | C37: 学院 | D37: 随从 | E37: 传说 | F37: 3 | G37: 2 | H37: 3 | I37: 1 | J37: 登场 | K37: 登场：复制你手牌中行动力消耗最低的战术牌。 | L37: battlecry:copyLowestSpell | M37: 3 | N37: 2 | O37: 3 | P37: =IF(OR(F37<>M37,IF(AND(G37="",N37=""),FALSE,G37<>N37),IF(AND(H37="",O37=""),FALSE,H37<>O37)),"已改","") | Q37: 可组
A38: nina | B38: 妮娜·索雷尔 | C38: 学院 | D38: 随从 | E38: 传说 | F38: 3 | G38: 3 | H38: 3 | I38: 1 | J38: 登场 | K38: 逆流 1：冻结目标所在阵位的所有敌方随从。 | L38: battlecry:freezeZone | M38: 3 | N38: 3 | O38: 3 | P38: =IF(OR(F38<>M38,IF(AND(G38="",N38=""),FALSE,G38<>N38),IF(AND(H38="",O38=""),FALSE,H38<>O38)),"已改","") | Q38: 可组
A39: lecturer | B39: 学院讲师 | C39: 学院 | D39: 随从 | E39: 普通 | F39: 3 | G39: 3 | H39: 2 | I39: 2 | J39: 登场 | K39: 逆流 1：抽 1 张牌。 | L39: battlecry:draw | M39: 3 | N39: 3 | O39: 2 | P39: =IF(OR(F39<>M39,IF(AND(G39="",N39=""),FALSE,G39<>N39),IF(AND(H39="",O39=""),FALSE,H39<>O39)),"已改","") | Q39: 可组
A40: spell_echo | B40: 法术回响 | C40: 学院 | D40: 随从 | E40: 稀有 | F40: 3 | G40: 2 | H40: 2 | I40: 2 | J40: 登场 | K40: 登场：检索一张战术牌。 | L40: battlecry:discover | M40: 3 | N40: 2 | O40: 2 | P40: =IF(OR(F40<>M40,IF(AND(G40="",N40=""),FALSE,G40<>N40),IF(AND(H40="",O40=""),FALSE,H40<>O40)),"已改","") | Q40: 可组
A41: zone_archivist | B41: 三阵记录员 | C41: 学院 | D41: 随从 | E41: 稀有 | F41: 3 | G41: 2 | H41: 4 | I41: 2 | J41: 被动 | K41: 被动：每当一个友方随从死亡，获得一张 0 行动力「记录弹」。 | L41: passive:deathRecordShot | M41: 3 | N41: 2 | O41: 4 | P41: =IF(OR(F41<>M41,IF(AND(G41="",N41=""),FALSE,G41<>N41),IF(AND(H41="",O41=""),FALSE,H41<>O41)),"已改","") | Q41: 可组
...

Sheet 衍生物
A1: 衍生物 / 召唤物
A2: 这些牌不由玩家直接组入牌组，但参与战斗；数值以游戏数据为准。
A4: ID | B4: 卡牌名 | C4: 阵营 | D4: 类型 | E4: 费用 | F4: 攻击 | G4: 生命 | H4: 关键词 | I4: 卡牌文本 | J4: 效果类型
A5: mining_permit | B5: 采掘许可 | C5: 中立 | D5: 战术 | E5: 0 | I5: 本回合获得 2 点行动力。 | J5: spell:gainMana
A6: losutai_imp | B6: 洛斯汰魔物 | C6: 西昭 | D6: 随从 | E6: 1 | F6: 1 | G6: 1 | H6: 余响 | I6: 余响：对随机敌方单位造成等同于攻击力的伤害（最高 5 点）。每回合开始时获得 +1/+1。 | J6: deathrattle:damageRandomEnemy；passive:turnGrowth
A7: losutai_beast | B7: 洛斯汰巨兽 | C7: 西昭 | D7: 随从 | E7: 3 | F7: 3 | G7: 3
A8: obsidian_spawn | B8: 黑曜碎片 | C8: 中立 | D8: 随从 | E8: 3 | F8: 3 | G8: 3
A9: grave_guard | B9: 墓钟守卫 | C9: 中立 | D9: 随从 | E9: 5 | F9: 5 | G9: 5
A10: astral_guardian | B10: 星界守卫 | C10: 中立 | D10: 随从 | E10: 3 | F10: 3 | G10: 3
A11: record_shot | B11: 记录弹 | C11: 学院 | D11: 战术 | E11: 0 | I11: 对一个敌方随从造成 1 点伤害。 | J11: spell:damage
A12: republic_recruit | B12: 共和国新兵 | C12: 共和国 | D12: 随从 | E12: 1 | F12: 1 | G12: 1

Sheet 对位矩阵
A1: 稳定版对位胜率矩阵
A2: 稳定版 20261020e24.5 · 每组对位 40 局，共 1440 局。胜率按分胜负对局计算；平局 7，卡死 0。绿=优，红=劣。
A4: 进攻方 \ 防守方 | B4: 普卫岛 | C4: 学院 | D4: 西昭 | E4: 共和国 | F4: 帝国 | G4: 灰港同盟 | H4: 总胜率 | I4: 样本
A5: 普卫岛 | B5: 0.625 | C5: 0.525 | D5: 0.65 | E5: 0.525 | F5: 0.425 | G5: 0.65 | H5: 0.53125 | I5: 480
A6: 学院 | B6: 0.4 | C6: 0.5 | D6: 0.725 | E6: 0.625 | F6: 0.4 | G6: 0.775 | H6: 0.5375 | I6: 480
A7: 西昭 | B7: 0.375 | C7: 0.45 | D7: 0.65 | E7: 0.4 | F7: 0.45 | G7: 0.675 | H7: 0.46458333 | I7: 480
A8: 共和国 | B8: 0.625 | C8: 0.5 | D8: 0.4 | E8: 0.525 | F8: 0.425 | G8: 0.55 | H8: 0.48958333 | I8: 480
A9: 帝国 | B9: 0.55 | C9: 0.7 | D9: 0.475 | E9: 0.7 | F9: 0.475 | G9: 0.775 | H9: 0.6125 | I9: 480
A10: 灰港同盟 | B10: 0.45 | C10: 0.275 | D10: 0.5 | E10: 0.375 | F10: 0.1 | G10: 0.625 | H10: 0.35 | I10: 480

Sheet 卡牌胜率
A1: 稳定版卡牌出场胜率
A2: 出场胜率 = 包含该卡出场且分出胜负的对局胜率，不是单卡因果/消融结果。用于找异常卡，不用于替代完整平衡测试。
A4: 卡牌ID | B4: 卡牌名 | C4: 阵营 | D4: 类型 | E4: 费用 | F4: 出场局数 | G4: 胜场 | H4: 出场胜率 | I4: 相对本阵营 | J4: 备注
A5: caravan_guard | B5: 商队护卫 | C5: 中立 | D5: 随从 | E5: 4 | F5: 1545 | G5: 841 | H5: 0.54433657 | I5: 0.018167693
A6: mist_scout | B6: 雾境斥候 | C6: 中立 | D6: 随从 | E6: 2 | F6: 1467 | G6: 773 | H6: 0.5269257 | I6: 0.00075682222
A7: gok_digger | B7: 戈克采掘者 | C7: 中立 | D7: 随从 | E7: 2 | F7: 1447 | G7: 828 | H7: 0.57221838 | I7: 0.046049506
A8: snow_medic | B8: 雪镇医者 | C8: 中立 | D8: 随从 | E8: 1 | F8: 1283 | G8: 658 | H8: 0.51286048 | I8: -0.013308393
A9: fog_sailor | B9: 雾港水手 | C9: 中立 | D9: 随从 | E9: 1 | F9: 917 | G9: 485 | H9: 0.52889858 | I9: 0.0027297059
A10: neutral_wayfarer | B10: 无籍旅者 | C10: 中立 | D10: 随从 | E10: 3 | F10: 856 | G10: 443 | H10: 0.51752336 | I10: -0.008645512
A11: formula_fix | B11: 公式修正 | C11: 学院 | D11: 战术 | E11: 4 | F11: 355 | G11: 184 | H11: 0.51830986 | I11: -0.019190141
A12: double_formula | B12: 双重公式 | C12: 学院 | D12: 战术 | E12: 3 | F12: 331 | G12: 174 | H12: 0.52567976 | I12: -0.011820242
A13: losutai_hunter | B13: 洛斯汰猎手 | C13: 西昭 | D13: 随从 | E13: 3 | F13: 319 | G13: 147 | H13: 0.46081505 | I13: -0.0037682863
A14: frost_seal | B14: 寒霜封印 | C14: 学院 | D14: 战术 | E14: 2 | F14: 316 | G14: 165 | H14: 0.5221519 | I14: -0.015348101
A15: coordination | B15: 协同调度 | C15: 普卫岛 | D15: 战术 | E15: 2 | F15: 304 | G15: 160 | H15: 0.52631579 | I15: -0.0049342105
A16: vein_scout | B16: 引脉斥候 | C16: 普卫岛 | D16: 随从 | E16: 1 | F16: 297 | G16: 155 | H16: 0.52188552 | I16: -0.0093644781
... A141: shield_marshal | B141: 持盾元帅 | C141: 共和国 | D141: 随从 | E141: 7 | F141: 20 | G141: 15 | H141: 0.75 | I141: 0.26041667
A142: vein_channel | B142: 流脉疏导 | C142: 中立 | D142: 战术 | E142: 2 | F142: 19 | G142: 10 | H142: 0.52631579 | I142: 0.00014691299 | J142: 样本不足
A143: bounty_hunter | B143: 赏金客 | C143: 中立 | D143: 随从 | E143: 3 | F143: 18 | G143: 10 | H143: 0.55555556 | I143: 0.029386679 | J143: 样本不足
A144: phalanx_executor | B144: 方阵执行官 | C144: 共和国 | D144: 随从 | E144: 4 | F144: 17 | G144: 8 | H144: 0.47058824 | I144: -0.018995098 | J144: 样本不足
A145: chrono_archivist | B145: 时序档案官 | C145: 中立 | D145: 随从 | E145: 8 | F145: 17 | G145: 11 | H145: 0.64705882 | I145: 0.12088995 | J145: 样本不足
A146: vein_warden | B146: 流脉守望者 | C146: 中立 | D146: 随从 | E146: 3 | F146: 17 | G146: 5 | H146: 0.29411765 | I146: -0.23205123 | J146: 样本不足
A147: smoke_screen | B147: 烟雾弹 | C147: 中立 | D147: 战术 | E147: 3 | F147: 17 | G147: 7 | H147: 0.41176471 | I147: -0.11440417 | J147: 样本不足
A148: reborn_sentry | B148: 回潮哨卫 | C148: 共和国 | D148: 随从 | E148: 3 | F148: 16 | G148: 9 | H148: 0.5625 | I148: 0.072916667 | J148: 样本不足
A149: mercenary | B149: 自由佣兵 | C149: 中立 | D149: 随从 | E149: 3 | F149: 16 | G149: 11 | H149: 0.6875 | I149: 0.16133112 | J149: 样本不足
A150: old_compass | B150: 旧罗盘 | C150: 中立 | D150: 战术 | E150: 3 | F150: 15 | G150: 8 | H150: 0.53333333 | I150: 0.0071644569 | J150: 样本不足
A151: vein_prism | B151: 流脉棱镜 | C151: 中立 | D151: 战术 | E151: 2 | F151: 15 | G151: 9 | H151: 0.6 | I151: 0.073831124 | J151: 样本不足
A152: traveling_healer | B152: 旅行医师 | C152: 中立 | D152: 随从 | E152: 3 | F152: 13 | G152: 8 | H152: 0.61538462 | I152: 0.089215739 | J152: 样本不足
A153: wandering_guard | B153: 荒野守卫 | C153: 中立 | D153: 随从 | E153: 3 | F153: 13 | G153: 6 | H153: 0.46153846 | I153: -0.064630415 | J153: 样本不足
... A196: iron_wall | B196: 铁壁令 | C196: 共和国 | D196: 战术 | E196: 2 | F196: 1 | G196: 0 | H196: 0 | I196: -0.48958333 | J196: 样本不足
A197: zone_archivist | B197: 三阵记录员 | C197: 学院 | D197: 随从 | E197: 3 | F197: 0 | G197: 0 | J197: 样本不足
A198: guard | B198: 保卫部步兵 | C198: 普卫岛 | D198: 随从 | E198: 3 | F198: 0 | G198: 0 | J198: 样本不足
A199: courier | B199: 协调部信使 | C199: 普卫岛 | D199: 随从 | E199: 1 | F199: 0 | G199: 0 | J199: 样本不足
A200: overload_gunner | B200: 反噬炮手 | C200: 帝国 | D200: 随从 | E200: 3 | F200: 0 | G200: 0 | J200: 样本不足
A201: echo_adept | B201: 回响学徒 | C201: 学院 | D201: 随从 | E201: 4 | F201: 0 | G201: 0 | J201: 样本不足
A202: echo_observer | B202: 回响观测者 | C202: 学院 | D202: 随从 | E202: 4 | F202: 0 | G202: 0 | J202: 样本不足
A203: vein_echo | B203: 地脉回响 | C203: 普卫岛 | D203: 战术 | E203: 2 | F203: 0 | G203: 0 | J203: 样本不足
A204: lecturer | B204: 学院讲师 | C204: 学院 | D204: 随从 | E204: 3 | F204: 0 | G204: 0 | J204: 样本不足
A205: empire_guard | B205: 帝国卫兵 | C205: 帝国 | D205: 随从 | E205: 2 | F205: 0 | G205: 0 | J205: 样本不足
A206: armor_forge | B206: 帝国锻炉 | C206: 帝国 | D206: 遗物 | E206: 3 | F206: 0 | G206: 0 | J206: 样本不足
A207: vein_attendant | B207: 引脉侍从 | C207: 普卫岛 | D207: 随从 | E207: 2 | F207: 0 | G207: 0 | J207: 样本不足
...

Sheet 阵营统计
A1: 阵营数值统计
A2: 统计表使用公式引用「卡牌数值」；改完 F/G/H 后，Excel 会自动重算。稳定版按当前数据统计；中立卡不计入六阵营明细。
A4: 阵营 | B4: 可组主卡 | C4: 可组遗物 | D4: 禁用 | E4: 实验 | F4: 平均费用 | G4: 平均攻击(随从) | H4: 平均生命(随从) | I4: 总条目
A5: 普卫岛 | B5: =COUNTIFS('卡牌数值'!$C$6:$C$249,A5,'卡牌数值'!$Q$6:$Q$249,"可组",'卡牌数值'!$D$6:$D$249,"<>遗物") | C5: =COUNTIFS('卡牌数值'!$C$6:$C$249,A5,'卡牌数值'!$Q$6:$Q$249,"遗物") | D5: =COUNTIFS('卡牌数值'!$C$6:$C$249,A5,'卡牌数值'!$Q$6:$Q$249,"禁用") | E5: =COUNTIFS('卡牌数值'!$C$6:$C$249,A5,'卡牌数值'!$Q$6:$Q$249,"实验") | F5: =IFERROR(AVERAGEIFS('卡牌数值'!$F$6:$F$249,'卡牌数值'!$C$6:$C$249,A5,'卡牌数值'!$Q$6:$Q$249,"可组",'卡牌数值'!$D$6:$D$249,"<>遗物"),"") | G5: =IFERROR(AVERAGEIFS('卡牌数值'!$G$6:$G$249,'卡牌数值'!$C$6:$C$249,A5,'卡牌数值'!$Q$6:$Q$249,"可组",'卡牌数值'!$D$6:$D$249,"随从"),"") | H5: =IFERROR(AVERAGEIFS('卡牌数值'!$H$6:$H$249,'卡牌数值'!$C$6:$C$249,A5,'卡牌数值'!$Q$6:$Q$249,"可组",'卡牌数值'!$D$6:$D$249,"随从"),"") | I5: =COUNTIF('卡牌数值'!$C$6:$C$249,A5)
A6: 学院 | B6: =COUNTIFS('卡牌数值'!$C$6:$C$249,A6,'卡牌数值'!$Q$6:$Q$249,"可组",'卡牌数值'!$D$6:$D$249,"<>遗物") | C6: =COUNTIFS('卡牌数值'!$C$6:$C$249,A6,'卡牌数值'!$Q$6:$Q$249,"遗物") | D6: =COUNTIFS('卡牌数值'!$C$6:$C$249,A6,'卡牌数值'!$Q$6:$Q$249,"禁用") | E6: =COUNTIFS('卡牌数值'!$C$6:$C$249,A6,'卡牌数值'!$Q$6:$Q$249,"实验") | F6: =IFERROR(AVERAGEIFS('卡牌数值'!$F$6:$F$249,'卡牌数值'!$C$6:$C$249,A6,'卡牌数值'!$Q$6:$Q$249,"可组",'卡牌数值'!$D$6:$D$249,"<>遗物"),"") | G6: =IFERROR(AVERAGEIFS('卡牌数值'!$G$6:$G$249,'卡牌数值'!$C$6:$C$249,A6,'卡牌数值'!$Q$6:$Q$249,"可组",'卡牌数值'!$D$6:$D$249,"随从"),"") | H6: =IFERROR(AVERAGEIFS('卡牌数值'!$H$6:$H$249,'卡牌数值'!$C$6:$C$249,A6,'卡牌数值'!$Q$6:$Q$249,"可组",'卡牌数值'!$D$6:$D$249,"随从"),"") | I6: =COUNTIF('卡牌数值'!$C$6:$C$249,A6)
A7: 西昭 | B7: =COUNTIFS('卡牌数值'!$C$6:$C$249,A7,'卡牌数值'!$Q$6:$Q$249,"可组",'卡牌数值'!$D$6:$D$249,"<>遗物") | C7: =COUNTIFS('卡牌数值'!$C$6:$C$249,A7,'卡牌数值'!$Q$6:$Q$249,"遗物") | D7: =COUNTIFS('卡牌数值'!$C$6:$C$249,A7,'卡牌数值'!$Q$6:$Q$249,"禁用") | E7: =COUNTIFS('卡牌数值'!$C$6:$C$249,A7,'卡牌数值'!$Q$6:$Q$249,"实验") | F7: =IFERROR(AVERAGEIFS('卡牌数值'!$F$6:$F$249,'卡牌数值'!$C$6:$C$249,A7,'卡牌数值'!$Q$6:$Q$249,"可组",'卡牌数值'!$D$6:$D$249,"<>遗物"),"") | G7: =IFERROR(AVERAGEIFS('卡牌数值'!$G$6:$G$249,'卡牌数值'!$C$6:$C$249,A7,'卡牌数值'!$Q$6:$Q$249,"可组",'卡牌数值'!$D$6:$D$249,"随从"),"") | H7: =IFERROR(AVERAGEIFS('卡牌数值'!$H$6:$H$249,'卡牌数值'!$C$6:$C$249,A7,'卡牌数值'!$Q$6:$Q$249,"可组",'卡牌数值'!$D$6:$D$249,"随从"),"") | I7: =COUNTIF('卡牌数值'!$C$6:$C$249,A7)
A8: 共和国 | B8: =COUNTIFS('卡牌数值'!$C$6:$C$249,A8,'卡牌数值'!$Q$6:$Q$249,"可组",'卡牌数值'!$D$6:$D$249,"<>遗物") | C8: =COUNTIFS('卡牌数值'!$C$6:$C$249,A8,'卡牌数值'!$Q$6:$Q$249,"遗物") | D8: =COUNTIFS('卡牌数值'!$C$6:$C$249,A8,'卡牌数值'!$Q$6:$Q$249,"禁用") | E8: =COUNTIFS('卡牌数值'!$C$6:$C$249,A8,'卡牌数值'!$Q$6:$Q$249,"实验") | F8: =IFERROR(AVERAGEIFS('卡牌数值'!$F$6:$F$249,'卡牌数值'!$C$6:$C$249,A8,'卡牌数值'!$Q$6:$Q$249,"可组",'卡牌数值'!$D$6:$D$249,"<>遗物"),"") | G8: =IFERROR(AVERAGEIFS('卡牌数值'!$G$6:$G$249,'卡牌数值'!$C$6:$C$249,A8,'卡牌数值'!$Q$6:$Q$249,"可组",'卡牌数值'!$D$6:$D$249,"随从"),"") | H8: =IFERROR(AVERAGEIFS('卡牌数值'!$H$6:$H$249,'卡牌数值'!$C$6:$C$249,A8,'卡牌数值'!$Q$6:$Q$249,"可组",'卡牌数值'!$D$6:$D$249,"随从"),"") | I8: =COUNTIF('卡牌数值'!$C$6:$C$249,A8)
A9: 帝国 | B9: =COUNTIFS('卡牌数值'!$C$6:$C$249,A9,'卡牌数值'!$Q$6:$Q$249,"可组",'卡牌数值'!$D$6:$D$249,"<>遗物") | C9: =COUNTIFS('卡牌数值'!$C$6:$C$249,A9,'卡牌数值'!$Q$6:$Q$249,"遗物") | D9: =COUNTIFS('卡牌数值'!$C$6:$C$249,A9,'卡牌数值'!$Q$6:$Q$249,"禁用") | E9: =COUNTIFS('卡牌数值'!$C$6:$C$249,A9,'卡牌数值'!$Q$6:$Q$249,"实验") | F9: =IFERROR(AVERAGEIFS('卡牌数值'!$F$6:$F$249,'卡牌数值'!$C$6:$C$249,A9,'卡牌数值'!$Q$6:$Q$249,"可组",'卡牌数值'!$D$6:$D$249,"<>遗物"),"") | G9: =IFERROR(AVERAGEIFS('卡牌数值'!$G$6:$G$249,'卡牌数值'!$C$6:$C$249,A9,'卡牌数值'!$Q$6:$Q$249,"可组",'卡牌数值'!$D$6:$D$249,"随从"),"") | H9: =IFERROR(AVERAGEIFS('卡牌数值'!$H$6:$H$249,'卡牌数值'!$C$6:$C$249,A9,'卡牌数值'!$Q$6:$Q$249,"可组",'卡牌数值'!$D$6:$D$249,"随从"),"") | I9: =COUNTIF('卡牌数值'!$C$6:$C$249,A9)
A10: 灰港同盟 | B10: =COUNTIFS('卡牌数值'!$C$6:$C$249,A10,'卡牌数值'!$Q$6:$Q$249,"可组",'卡牌数值'!$D$6:$D$249,"<>遗物") | C10: =COUNTIFS('卡牌数值'!$C$6:$C$249,A10,'卡牌数值'!$Q$6:$Q$249,"遗物") | D10: =COUNTIFS('卡牌数值'!$C$6:$C$249,A10,'卡牌数值'!$Q$6:$Q$249,"禁用") | E10: =COUNTIFS('卡牌数值'!$C$6:$C$249,A10,'卡牌数值'!$Q$6:$Q$249,"实验") | F10: =IFERROR(AVERAGEIFS('卡牌数值'!$F$6:$F$249,'卡牌数值'!$C$6:$C$249,A10,'卡牌数值'!$Q$6:$Q$249,"可组",'卡牌数值'!$D$6:$D$249,"<>遗物"),"") | G10: =IFERROR(AVERAGEIFS('卡牌数值'!$G$6:$G$249,'卡牌数值'!$C$6:$C$249,A10,'卡牌数值'!$Q$6:$Q$249,"可组",'卡牌数值'!$D$6:$D$249,"随从"),"") | H10: =IFERROR(AVERAGEIFS('卡牌数值'!$H$6:$H$249,'卡牌数值'!$C$6:$C$249,A10,'卡牌数值'!$Q$6:$Q$249,"可组",'卡牌数值'!$D$6:$D$249,"随从"),"") | I10: =COUNTIF('卡牌数值'!$C$6:$C$249,A10)
A11: 合计 | B11: =SUM(B5:B10) | C11: =SUM(C5:C10) | D11: =SUM(D5:D10) | E11: =SUM(E5:E10) | F11: =IFERROR(AVERAGE(F5:F10),"") | G11: =IFERROR(AVERAGE(G5:G10),"") | H11: =IFERROR(AVERAGE(H5:H10),"") | I11: =SUM(I5:I10)
A13: 全局
A14: 可组主卡 | B14: =COUNTIFS('卡牌数值'!$Q$6:$Q$249,"可组",'卡牌数值'!$D$6:$D$249,"<>遗物")
A15: 可组遗物 | B15: =COUNTIFS('卡牌数值'!$Q$6:$Q$249,"遗物")
A16: 实验牌 | B16: =COUNTIF('卡牌数值'!$Q$6:$Q$249,"实验")
A17: 禁用牌 | B17: =COUNTIF('卡牌数值'!$Q$6:$Q$249,"禁用")
A18: 可收藏条目 | B18: =COUNTA('卡牌数值'!$A$6:$A$249)
A19: 衍生物 | B19: =COUNTA(衍生物!$A$5:$A$12)
A20: 总卡牌条目 | B20: =B14+B15+B16+B17+B19

Sheet 说明
A1: 卡牌数值表 · 使用说明
A3: 版本 | B3: 稳定版构建 20261020e24.5；本表不包含抢先版数据。
A4: 编辑范围 | B4: 只改「卡牌数值」的 F 费用、G 攻击、H 生命三列（黄色）。M-O 是原始值，P 列自动显示「已改」。
A5: 空白值 | B5: 战术/遗物没有攻击或生命时保持空白；不要填 0，否则会被视为改动。
A6: 牌组上限 | B6: 按稀有度/类型自动记录：遗物 1、传说 1、阵型 2、其他 2。
A7: 状态 | B7: 可组 = 正常组卡池；遗物 = 可组遗物。稳定版没有实验或禁用条目。
A8: 正常卡池 | B8: 稳定版共 244 个可收藏条目；各阵营数量见「阵营统计」。
A9: 实验牌 | B9: 稳定版不含实验牌；抢先版实验内容不会进入本表。
A10: 改动后 | B10: 在 Excel 里调整只影响这份表，不会自动写回游戏；把改动同步到稳定版 data.js 后重新测试、打包。
A11: 统计 | B11: 「阵营统计」和「稀有度」使用公式；Excel 打开或修改后会自动重算。
A12: 提示 | B12: 先筛选「状态」=可组，再按阵营/费用调整，避免改错遗物。

Sheet 稀有度
A1: 稀有度分布
A2: 统计表使用公式引用「卡牌数值」；修改后自动重算。
A3: 稀有度 | B3: 可收藏数量 | C3: 平均费用 | D3: 可组主卡数
A4: 普通 | B4: =COUNTIF('卡牌数值'!$E$6:$E$249,A4) | C4: =IFERROR(AVERAGEIFS('卡牌数值'!$F$6:$F$249,'卡牌数值'!$E$6:$E$249,A4),"") | D4: =COUNTIFS('卡牌数值'!$E$6:$E$249,A4,'卡牌数值'!$Q$6:$Q$249,"可组")
A5: 稀有 | B5: =COUNTIF('卡牌数值'!$E$6:$E$249,A5) | C5: =IFERROR(AVERAGEIFS('卡牌数值'!$F$6:$F$249,'卡牌数值'!$E$6:$E$249,A5),"") | D5: =COUNTIFS('卡牌数值'!$E$6:$E$249,A5,'卡牌数值'!$Q$6:$Q$249,"可组")
A6: 史诗 | B6: =COUNTIF('卡牌数值'!$E$6:$E$249,A6) | C6: =IFERROR(AVERAGEIFS('卡牌数值'!$F$6:$F$249,'卡牌数值'!$E$6:$E$249,A6),"") | D6: =COUNTIFS('卡牌数值'!$E$6:$E$249,A6,'卡牌数值'!$Q$6:$Q$249,"可组")
A7: 传说 | B7: =COUNTIF('卡牌数值'!$E$6:$E$249,A7) | C7: =IFERROR(AVERAGEIFS('卡牌数值'!$F$6:$F$249,'卡牌数值'!$E$6:$E$249,A7),"") | D7: =COUNTIFS('卡牌数值'!$E$6:$E$249,A7,'卡牌数值'!$Q$6:$Q$249,"可组")
